Workbook

Sheet 様式電⑧-2電圧降下（分岐）
U1: （様式 電-8-2）
A2: 電路計算書（分岐配線用） | H2: =+#REF!&#REF! -> #REF! | U2: =+#REF! -> #REF!
B3: 盤名称: | C3: OA-2-1
A4: 回路番号 | B4: 電気方式 | C4: 電 圧 | D4: 配線用遮断器定格電流 | E4: 系 統 | I4: こう長 | J4: 負荷名称 | K4: 負荷容量 | L4: 設計負荷電流又は最大使用電流 | M4: 電気方式 による 係数 | N4: 電圧降下による電線太さ | O4: 電線及びケーブル | T4: 電圧降下 | U4: 許容電圧降下
O5: 種別及び断面積 | Q5: 配線 方式 | R5: ケーブルラック配線の許容電流低減率 | S5: 許容電流
C6: ［V］ | D6: ［A] | I6: ℓ［m］ | K6: ［VA］［W］ | L6: Ｉ［A］ | M6: K' | N6: A[mm2] | O6: A［mm2］ | S6: ［A］ | T6: e［V］ | U6: ［V］
A83: 分岐配線における電圧降下の算出 | H83: ここに、 | I83: e | J83: ： 電圧降下［V］ | M83: 電圧降下による電線太さ
I84: K' | J84: ： 電気方式による係数
I85: I | J85: ： 設計負荷電流又は最大使用電流［A］
I86: ℓ | J86: ： こう長［m］
I87: A | J87: ： 電線の断面積［mm2］
U88: H30

Sheet 電圧降下
A2: 50Hz | B2: インピーダンス | D2: FPT | I2: 60Hz | J2: インピーダンス | L2: FPT
A3: θ | B3: 0.95 | C3: 許容電流 | D3: 許容電流 | I3: θ | J3: 0.95 | K3: 許容電流 | L3: 許容電流 | AD3: 60Hz | AE3: インピーダンス
A4: 14 | B4: 1.66 | C4: 86 | D4: 73 | I4: 14 | J4: 1.66 | K4: 86 | L4: 73 | AD4: θ | AE4: 0.95 | AF4: 0.8 | AG4: 許容電流
A5: 22 | B5: 1.06 | C5: 110 | D5: 97 | I5: 22 | J5: 1.06 | K5: 110 | L5: 97 | AD5: 5.5 | AE5: 4.16 | AF5: 3.54 | AG5: 44
A6: 38 | B6: 0.624 | C6: 155 | D6: 135 | I6: 38 | J6: 0.631 | K6: 155 | L6: 135 | AD6: 8 | AE6: 2.86 | AF6: 2.45 | AG6: 54
A7: 60 | B7: 0.406 | C7: 210 | D7: 180 | I7: 60 | J7: 0.411 | K7: 210 | L7: 180
A8: 100 | B8: 0.255 | C8: 290 | D8: 265 | I8: 100 | J8: 0.26 | K8: 290 | L8: 265
A9: 150 | B9: 0.177 | C9: 380 | D9: 345 | I9: 150 | J9: 0.184 | K9: 380 | L9: 345
A10: 200 | B10: 0.142 | C10: 465 | D10: 395 | I10: 200 | J10: 0.147 | K10: 465 | L10: 395
A11: 250 | B11: 0.119 | C11: 535 | I11: 250 | J11: 0.125 | K11: 535
A12: 150*2 | B12: =0.177/2 -> 0.0885 | C12: =380*2 -> 760 | I12: 150*2 | J12: =0.184/2 -> 0.092 | K12: =380*2 -> 760
A13: 200*2 | B13: =0.142/2 -> 0.071 | C13: =465*2 -> 930 | I13: 200*2 | J13: =0.147/2 -> 0.0735 | K13: =465*2 -> 930
A14: 250*2 | B14: =0.119/2 -> 0.0595 | C14: =535*2 -> 1070 | I14: 250*2 | J14: =0.125/2 -> 0.0625 | K14: =535*2 -> 1070
A15: θ | B15: 0.8 | I15: θ | J15: θ.8
A16: 14 | B16: 1.43 | I16: 14 | J16: 1.44
A17: 22 | B17: 0.926 | I17: 22 | J17: 0.938
A18: 38 | B18: 0.558 | I18: 38 | J18: 0.57
A19: 60 | B19: 0.372 | I19: 60 | J19: 0.384
A20: 100 | B20: 0.244 | I20: 100 | J20: 0.255
A21: 150 | B21: 0.178 | I21: 150 | J21: 0.189
A22: 200 | B22: 0.148 | I22: 200 | J22: 0.159
A23: 250 | B23: 0.129 | I23: 250 | J23: 0.139
A24: 150*2 | B24: =0.178/2 -> 0.089 | I24: 150*2 | J24: =0.189/2 -> 0.0945
A25: 200*2 | B25: =0.148/2 -> 0.074 | I25: 200*2 | J25: =0.159/2 -> 0.0795
A26: 250*2 | B26: =0.129/2 -> 0.0645 | I26: 250*2 | J26: =0.139/2 -> 0.0695
Y29: （様式 電-8-1）
A30: 電路計算書（幹線用） | E30: 建物名称 | Z30: 45658
A31: 周波数 | B31: 60
A32: 受変電設備等 | E32: 幹線 | L32: 負荷 | P32: 許容電流 | V32: 電圧降下
A33: 幹線番号 又は名称 | B33: 電気方式 | C33: 電 圧 | D33: 幹線保護用遮断器定格電流 | E33: 系 統 | I33: こう長 | J33: 幹線分岐 | L33: 負荷 名称 | M33: 負荷 容量 [kVA] [ kW ] | N33: 主幹器具 定格電流 | O33: 設計負荷 電流 | P33: 種別及び導体太さ | R33: 配線 方式 | S33: 許容 電流 ＊ | T33: ケーブルラック配線 | V33: 電気方式 による 係数 | W33: 負荷の 力率 | X33: 電線１km当たりのインピーダンス | Y33: e | Z33: 許容電圧降下 | AA33: 備考
J34: 分岐幹線の 許容電流 | T34: 許容電流 低減率 | U34: 許容電流 | AC34: 分岐 | AF34: 充足率 | AG34: 電圧降下 判定 | AH34: 電流値 判定 | AI34: 開閉器 判定
C35: ［V］ | D35: ［A] | I35: ℓ［m］ | J35: [A] | N35: ［A] | O35: Ｉ［A］ | P35: A［mm2］ | S35: ［A］ | U35: ［A］ | V35: K | W35: cosθ | X35: Z［Ω/km］ | Y35: ［V］ | Z35: ［V］ | AC35: 亘長
A36: 電灯No.1 | AF36: =+Y36/Z36 -> #DIV/0! | AG36: =+IF(AF36<0.8,"〇","×") -> #DIV/0! | AH36: =+IF(S36>D36,"〇","×") -> × | AI36: =+IF(D36>O36,"〇","×") -> ×
A40: ①L-101 | B40: 単相3線式 | C40: 100/200 | D40: 400 | I40: =+VLOOKUP(L40,長さ!A$4:B$100,2,FALSE) -> 67 | L40: 1L-1 | M40: 70.7 | N40: =+D40 -> 400 | O40: =+M40/0.2 -> 353.5 | P40: CVT | Q40: 250 | R40: ｹｰﾌﾞﾙﾗｯｸ配線 | S40: =+IF($B$31=50,ROUND(VLOOKUP(Q40,$A$4:$C$14,3,FALSE),1),ROUND(VLOOKUP(Q40,$I$4:$K$14,3,FALSE),1)) -> 535 | T40: 0.7 | U40: =+IF(T40="","-",T40*S40) -> 374.5 | V40: 1 | W40: 0.95 | X40: =+IF($B$31=50,VLOOKUP(Q40,$A$4:$C$14,2,FALSE),VLOOKUP(Q40,$I$4:$K$14,2,FALSE)) -> 0.125 | Y40: =+V40*O40*I40*X40/1000 -> 2.9605625 | Z40: =+IF(I40<120,3,IF(I40<200,4,5)) -> 3 | AF40: =+Y40/Z40 -> 0.98685417 | AG40: =+IF(AF40<1,"〇","×") -> 〇 | AH40: =+IF(U40>D40,"〇","×") -> × | AI40: =+IF(D40>O40,"〇","×") -> 〇
A44: ②L-102 | B44: 単相3線式 | C44: 100/200 | D44: 225 | I44: 123 | L44: 2L-1 | M44: 39.9 | N44: =+D44 -> 225 | O44: =+M44/0.2 -> 199.5 | P44: CVT | Q44: 200 | R44: ｹｰﾌﾞﾙﾗｯｸ配線 | S44: =+IF($B$31=50,ROUND(VLOOKUP(Q44,$A$4:$C$14,3,FALSE),1),ROUND(VLOOKUP(Q44,$I$4:$K$14,3,FALSE),1)) -> 465 | T44: 0.7 | U44: =+IF(T44="","-",T44*S44) -> 325.5 | V44: 1 | W44: 0.95 | X44: =+IF($B$31=50,VLOOKUP(Q44,$A$4:$C$14,2,FALSE),VLOOKUP(Q44,$I$4:$K$14,2,FALSE)) -> 0.147 | Y44: =+V44*O44*I44*X44/1000 -> 3.6071595 | Z44: =+IF(I44<120,3,IF(I44<200,4,5)) -> 4 | AF44: =+Y44/Z44 -> 0.90178987 | AG44: =+IF(AF44<1,"〇","×") -> 〇 | AH44: =+IF(U44>D44,"〇","×") -> 〇 | AI44: =+IF(D44>O44,"〇","×") -> 〇
A48: ③L-103 | B48: 単相3線式 | C48: 100/200 | D48: 175 | I48: 201 | L48: 3L-1 | M48: 30.1 | N48: =+D48 -> 175 | O48: =+M48/0.2 -> 150.5 | P48: CVT | Q48: 200 | R48: ｹｰﾌﾞﾙﾗｯｸ配線 | S48: =+IF($B$31=50,ROUND(VLOOKUP(Q48,$A$4:$C$14,3,FALSE),1),ROUND(VLOOKUP(Q48,$I$4:$K$14,3,FALSE),1)) -> 465 | T48: 0.7 | U48: =+IF(T48="","-",T48*S48) -> 325.5 | V48: 1 | W48: 0.95 | X48: =+IF($B$31=50,VLOOKUP(Q48,$A$4:$C$14,2,FALSE),VLOOKUP(Q48,$I$4:$K$14,2,FALSE)) -> 0.147 | Y48: =+V48*O48*I48*X48/1000 -> 4.4468235 | Z48: =+IF(I48<120,3,IF(I48<200,4,5)) -> 5 | AF48: =+Y48/Z48 -> 0.8893647 | AG48: =+IF(AF48<1,"〇","×") -> 〇 | AH48: =+IF(U48>D48,"〇","×") -> 〇 | AI48: =+IF(D48>O48,"〇","×") -> 〇
AF52: =+Y52/Z52 -> #DIV/0! | AG52: =+IF(AF52<1,"〇","×") -> #DIV/0! | AH52: =+IF(U52>D52,"〇","×") -> × | AI52: =+IF(D52>O52,"〇","×") -> ×
AF56: =+Y56/Z56 -> #DIV/0! | AG56: =+IF(AF56<1,"〇","×") -> #DIV/0! | AH56: =+IF(U56>D56,"〇","×") -> × | AI56: =+IF(D56>O56,"〇","×") -> ×
A60: ④LG-101 | B60: 単相3線式 | C60: 100/200 | D60: 125 | I60: 62 | L60: 1～3L-1 | M60: =+M64+M72 -> 24.5 | O60: =+M60/0.2 -> 122.5 | P60: CVT | Q60: 100 | R60: ｹｰﾌﾞﾙﾗｯｸ配線 | S60: =+IF($B$31=50,ROUND(VLOOKUP(Q60,$A$4:$C$14,3,FALSE),1),ROUND(VLOOKUP(Q60,$I$4:$K$14,3,FALSE),1)) -> 290 | T60: 0.7 | U60: =+IF(T60="","-",T60*S60) -> 203 | V60: 1 | W60: 0.95 | X60: =+IF($B$31=50,VLOOKUP(Q60,$A$4:$C$14,2,FALSE),VLOOKUP(Q60,$I$4:$K$14,2,FALSE)) -> 0.26 | Y60: =+V60*O60*I60*X60/1000 -> 1.9747 | Z60: =+IF(I60<120,3,IF(I60<200,4,5)) -> 3 | AA60: A | AF60: =+Y60/Z60 -> 0.65823333 | AG60: =+IF(AF60<1,"〇","×") -> 〇 | AH60: =+IF(U60>D60,"〇","×") -> 〇 | AI60: =+IF(D60>O60,"〇","×") -> 〇
A64: LG-101-1 | B64: 単相3線式 | C64: 100/200 | I64: 5 | J64: L≦8m | K64: 35％ | L64: 1L-1 | M64: 12 | N64: 75 | O64: =+M64/0.2 -> 60 | P64: CVT | Q64: 14 | R64: 配管配線 | S64: =+IF($B$31=50,ROUND(VLOOKUP(Q64,$A$4:$C$14,3,FALSE),1),ROUND(VLOOKUP(Q64,$I$4:$K$14,3,FALSE),1)) -> 86 | T64: 1 | U64: =+IF(T64="","-",T64*S64) -> 86 | V64: 1 | W64: 0.95 | X64: =+IF($B$31=50,VLOOKUP(Q64,$A$4:$C$14,2,FALSE),VLOOKUP(Q64,$I$4:$K$14,2,FALSE)) -> 1.66 | Y64: =+V64*O64*I64*X64/1000 -> 0.498 | Z64: =+IF(I64<120,3,IF(I64<200,4,5)) -> 3 | AA64: 1 | AF64: =+Y64/Z64 -> 0.166 | AG64: =+IF(AF64<1,"〇","×") -> 〇 | AH64: =+IF(U64>D64,"〇","×") -> 〇 | AI64: =+IF(D64>O64,"〇","×") -> ×
...

Sheet 長さ
A1: 亘長
D2: 1F | E2: 4.85 | F2: 2F | G2: 4.65 | H2: 3F | I2: 4.5 | J2: 4F | K2: 4.5 | L2: 5F | M2: 4.5 | N2: 6F | O2: 4.5 | P2: RF | Q2: 3 | R2: 外構 | V2: QB
A3: 盤名称 | B3: 合計（×1.1） | C3: 計 | D3: 横 | E3: 縦 | F3: 横 | G3: 縦 | H3: 横 | I3: 縦 | J3: 横 | K3: 縦 | L3: 横 | M3: 縦 | N3: 横 | O3: 縦 | P3: 横 | Q3: 縦 | R3: 横 | S3: 縦 | T3: 横 | U3: 縦 | V3: 横 | W3: 縦
A4: 1L-1 | B4: =ROUNDUP(C4*1.1,0) -> 67 | C4: =+SUM(D4:AG4) -> 60.5 | D4: 35.7 | E4: 3.9 | V4: 17 | W4: 3.9
A5: 2L-1 | B5: =ROUNDUP(C5*1.1,0) -> 74 | C5: =+SUM(D5:AG5) -> 66.4 | D5: 35.3 | F5: 1.8 | G5: =4.7+3.7 -> 8.4 | V5: 17 | W5: 3.9
A6: 3L-1 | B6: =ROUNDUP(C6*1.1,0) -> 78 | C6: =+SUM(D6:AG6) -> 70.7 | D6: 35.3 | G6: 4.7 | H6: 1.8 | I6: =4.5+3.5 -> 8 | V6: 17 | W6: 3.9
A7: 4L-1 | B7: =ROUNDUP(C7*1.1,0) -> 83 | C7: =+SUM(D7:AG7) -> 75.2 | D7: 35.3 | G7: 4.7 | I7: 4.5 | J7: 1.8 | K7: 8 | V7: 17 | W7: 3.9
A8: 5L-1 | B8: =ROUNDUP(C8*1.1,0) -> 88 | C8: =+SUM(D8:AG8) -> 79.7 | D8: 35.3 | G8: 4.7 | I8: 4.5 | K8: 4.5 | L8: 1.8 | M8: 8 | V8: 17 | W8: 3.9
A9: 6L-1 | B9: =ROUNDUP(C9*1.1,0) -> 93 | C9: =+SUM(D9:AG9) -> 84.2 | D9: 35.3 | G9: 4.7 | I9: 4.5 | K9: 4.5 | M9: 4.5 | N9: 1.8 | O9: 8 | V9: 17 | W9: 3.9
B10: =ROUNDUP(C10*1.1,0) -> 0 | C10: =+SUM(D10:AG10) -> 0
B11: =ROUNDUP(C11*1.1,0) -> 0 | C11: =+SUM(D11:AG11) -> 0
B12: =ROUNDUP(C12*1.1,0) -> 0 | C12: =+SUM(D12:AG12) -> 0
B13: =ROUNDUP(C13*1.1,0) -> 0 | C13: =+SUM(D13:AG13) -> 0
B14: =ROUNDUP(C14*1.1,0) -> 0 | C14: =+SUM(D14:AG14) -> 0
B15: =ROUNDUP(C15*1.1,0) -> 0 | C15: =+SUM(D15:AG15) -> 0
B16: =ROUNDUP(C16*1.1,0) -> 0 | C16: =+SUM(D16:AG16) -> 0
B17: =ROUNDUP(C17*1.1,0) -> 0 | C17: =+SUM(D17:AG17) -> 0
B18: =ROUNDUP(C18*1.1,0) -> 0 | C18: =+SUM(D18:AG18) -> 0
B19: =ROUNDUP(C19*1.1,0) -> 0 | C19: =+SUM(D19:AG19) -> 0
B20: =ROUNDUP(C20*1.1,0) -> 0 | C20: =+SUM(D20:AG20) -> 0
B21: =ROUNDUP(C21*1.1,0) -> 0 | C21: =+SUM(D21:AG21) -> 0
... B53: =ROUNDUP(C53*1.1,0) -> 0 | C53: =+SUM(D53:AG53) -> 0
B54: =ROUNDUP(C54*1,0) -> 0 | C54: =+SUM(D54:AG54) -> 0
B55: =ROUNDUP(C55*1,0) -> 0 | C55: =+SUM(D55:AG55) -> 0
B56: =ROUNDUP(C56*1,0) -> 0 | C56: =+SUM(D56:AG56) -> 0
B57: =ROUNDUP(C57*1,0) -> 0 | C57: =+SUM(D57:AG57) -> 0
B58: =ROUNDUP(C58*1,0) -> 0 | C58: =+SUM(D58:AG58) -> 0
B59: =ROUNDUP(C59*1,0) -> 0 | C59: =+SUM(D59:AG59) -> 0
B60: =ROUNDUP(C60*1,0) -> 0 | C60: =+SUM(D60:AG60) -> 0
B61: =ROUNDUP(C61*1,0) -> 0 | C61: =+SUM(D61:AG61) -> 0
B62: =ROUNDUP(C62*1,0) -> 0 | C62: =+SUM(D62:AG62) -> 0
B63: =ROUNDUP(C63*1,0) -> 0 | C63: =+SUM(D63:AG63) -> 0
B64: =ROUNDUP(C64*1,0) -> 0 | C64: =+SUM(D64:AG64) -> 0
B65: =ROUNDUP(C65*1,0) -> 0 | C65: =+SUM(D65:AG65) -> 0
... B100: =ROUNDUP(C100*1,0) -> 0 | C100: =+SUM(D100:AG100) -> 0

Sheet ラック
B1: ■ケーブルラック計算表
B2: □受変電設備 | G2: 外形＋ | H2: 10
B3: フロア | C3: 幹線番号 | D3: 負荷名称 | E3: 幹線 サイズ | F3: 本数 | G3: 外形 | H3: QB | I3: EPS縦
C5: =+電圧降下!A40 -> ①L-101 | D5: =+電圧降下!L40 -> 1L-1 | E5: =+電圧降下!Q40 -> 250 | F5: 1 | G5: =IF(E5=8,16,IF(E5=14,21,IF(E5=22,24,IF(E5=38,28,IF(E5=60,33,IF(E5=100,41,IF(E5=150,47,IF(E5=200,55,IF(E5=250,60,"-")))))))))*F5 -> 60 | H5: =G5+$H$2 -> 70
C6: =+電圧降下!A44 -> ②L-102 | D6: =+電圧降下!L44 -> 2L-1 | E6: =+電圧降下!Q44 -> 200 | F6: 1 | G6: =IF(E6=8,16,IF(E6=14,21,IF(E6=22,24,IF(E6=38,28,IF(E6=60,33,IF(E6=100,41,IF(E6=150,47,IF(E6=200,55,IF(E6=250,60,"-")))))))))*F6 -> 55 | H6: =G6+$H$2 -> 65 | I6: =+H6 -> 65
C7: =+電圧降下!A48 -> ③L-103 | D7: =+電圧降下!L48 -> 3L-1 | E7: =+電圧降下!Q48 -> 200 | F7: 1 | G7: =IF(E7=8,16,IF(E7=14,21,IF(E7=22,24,IF(E7=38,28,IF(E7=60,33,IF(E7=100,41,IF(E7=150,47,IF(E7=200,55,IF(E7=250,60,"-")))))))))*F7 -> 55 | H7: =G7+$H$2 -> 65 | I7: =+H7 -> 65
C8: =+電圧降下!A60 -> ④LG-101 | D8: =+電圧降下!L60 -> 1～3L-1 | E8: =+電圧降下!Q60 -> 100 | F8: 1 | G8: =IF(E8=8,16,IF(E8=14,21,IF(E8=22,24,IF(E8=38,28,IF(E8=60,33,IF(E8=100,41,IF(E8=150,47,IF(E8=200,55,IF(E8=250,60,"-")))))))))*F8 -> 41 | H8: =G8+$H$2 -> 51 | I8: =+H8 -> 51
C9: =+電圧降下!A96 -> ⑤LE-101 | D9: =+電圧降下!L96 -> 非常ｺﾝｾﾝﾄ | E9: =+電圧降下!Q96 -> 22 | F9: 2 | G9: =IF(E9=8,16,IF(E9=14,21,IF(E9=22,24,IF(E9=38,28,IF(E9=60,33,IF(E9=100,41,IF(E9=150,47,IF(E9=200,55,IF(E9=250,60,"-")))))))))*F9 -> 48 | H9: =G9+$H$2 -> 58 | I9: =+H9 -> 58
C10: =+電圧降下!A143 -> ①P-101 | D10: =+電圧降下!L143 -> 1P-1 | E10: =+電圧降下!Q143 -> 60 | F10: 1 | G10: =IF(E10=8,16,IF(E10=14,21,IF(E10=22,24,IF(E10=38,28,IF(E10=60,33,IF(E10=100,41,IF(E10=150,47,IF(E10=200,55,IF(E10=250,60,"-")))))))))*F10 -> 33 | H10: =G10+$H$2 -> 43
C11: =+電圧降下!A147 -> ②P-102 | D11: =+電圧降下!L147 -> 2P-1 | E11: =+電圧降下!Q147 -> 100 | F11: 1 | G11: =IF(E11=8,16,IF(E11=14,21,IF(E11=22,24,IF(E11=38,28,IF(E11=60,33,IF(E11=100,41,IF(E11=150,47,IF(E11=200,55,IF(E11=250,60,"-")))))))))*F11 -> 41 | H11: =G11+$H$2 -> 51 | I11: =+H11 -> 51
C12: =+電圧降下!A151 -> ③P-103 | D12: =+電圧降下!L151 -> 3P-1 | E12: =+電圧降下!Q151 -> 100 | F12: 1 | G12: =IF(E12=8,16,IF(E12=14,21,IF(E12=22,24,IF(E12=38,28,IF(E12=60,33,IF(E12=100,41,IF(E12=150,47,IF(E12=200,55,IF(E12=250,60,"-")))))))))*F12 -> 41 | H12: =G12+$H$2 -> 51 | I12: =+H12 -> 51
C13: =+電圧降下!A159 -> ④P-104 | D13: =+電圧降下!L159 -> 1P-1 | E13: =+電圧降下!Q159 -> 60 | F13: 1 | G13: =IF(E13=8,16,IF(E13=14,21,IF(E13=22,24,IF(E13=38,28,IF(E13=60,33,IF(E13=100,41,IF(E13=150,47,IF(E13=200,55,IF(E13=250,60,"-")))))))))*F13 -> 33 | H13: =G13+$H$2 -> 43
C14: =+電圧降下!A167 -> ⑤P-105 | D14: =+電圧降下!L167 -> 1P-1 | E14: =+電圧降下!Q167 -> 100 | F14: 1 | G14: =IF(E14=8,16,IF(E14=14,21,IF(E14=22,24,IF(E14=38,28,IF(E14=60,33,IF(E14=100,41,IF(E14=150,47,IF(E14=200,55,IF(E14=250,60,"-")))))))))*F14 -> 41 | H14: =G14+$H$2 -> 51
G29: 合計ケーブルサイズ W≧1.2{Σ(D+10)+60} | H29: =(SUM(H4:H27)+60)*1.2 -> 729.6 | I29: =(SUM(I4:I27)+60)*1.2 -> 481.2
G30: 選定ケーブルラックサイズ | H30: 800×1 | I30: 600×3

Sheet 亘長
A1: 亘長
C2: 外構 | E2: 1F | G2: 2F | I2: 3F | K2: 4F
A3: 名称 | B3: 合計 | C3: 平 | D3: 立 | E3: 平 | F3: 立 | G3: 平 | H3: 立 | I3: 平 | J3: 立 | K3: 平 | L3: 立 | M3: 盤側 | N3: QB側
A4: 1L-1 | B4: =+SUM(C4:N4) -> 43 | C4: 25 | E4: 5 | F4: 6 | M4: 5 | N4: 2
A5: 2L-1 | B5: =+SUM(C5:N5) -> 54 | C5: 25 | F5: 6 | G5: 10 | H5: 6 | M5: 5 | N5: 2
A6: 3L-1 | B6: =+SUM(C6:N6) -> 60 | C6: 25 | F6: 6 | H6: 6 | I6: 10 | J6: 6 | M6: 5 | N6: 2
A7: 4L-1 | B7: =+SUM(C7:N7) -> 65 | C7: 25 | F7: 6 | H7: 6 | J7: 6 | K7: 10 | L7: 5 | M7: 5 | N7: 2
A8: 計装分電盤 | B8: =+SUM(C8:N8) -> 75 | C8: 25 | F8: 6 | H8: 6 | J8: 6 | K8: 20 | L8: 5 | M8: 5 | N8: 2
A9: 1P-1 | B9: =+SUM(C9:N9) -> 43 | C9: 25 | E9: 5 | F9: 6 | M9: 5 | N9: 2
A10: 1P-2 | B10: =+SUM(C10:N10) -> 21 | C10: 17 | M10: 2 | N10: 2
A11: 2P-1 | B11: =+SUM(C11:N11) -> 54 | C11: 25 | F11: 6 | G11: 10 | H11: 6 | M11: 5 | N11: 2
A12: 3P-1 | B12: =+SUM(C12:N12) -> 60 | C12: 25 | F12: 6 | H12: 6 | I12: 10 | J12: 6 | M12: 5 | N12: 2
A13: 4P-1 | B13: =+SUM(C13:N13) -> 70 | C13: 25 | F13: 6 | H13: 6 | J13: 6 | K13: 15 | L13: 5 | M13: 5 | N13: 2
A14: RP-1 | B14: =+SUM(C14:N14) -> 17 | D14: 10 | M14: 5 | N14: 2
A16: ELV | B16: =+SUM(C16:N16) -> 70 | C16: 25 | F16: 6 | H16: 6 | J16: 6 | K16: 15 | L16: 5 | M16: 5 | N16: 2
B17: =+SUM(C17:N17) -> 0
A18: MP-01 | B18: =+SUM(C18:N18) -> 70 | C18: 25 | F18: 6 | H18: 6 | J18: 6 | K18: 15 | L18: 5 | M18: 5 | N18: 2
B26: =+SUM(C26:N26) -> 0
B27: =+SUM(C27:N27) -> 0
B28: =+SUM(C28:N28) -> 0
B29: =+SUM(C29:N29) -> 0
